Workbook

Sheet Visual_Dashbord
A1: Daily Progress Report | G1: Progress Date : | H1: 46188
A2: S No. | B2: description | C2: Uom | D2: Scope | E2: Cum.Executed Qty till Progress date | F2: Balance Qty | G2: Progress % w.r.t. scope | H2: Remarks
A3: I | B3: Civil1_Road Over Brige(ROB)
A4: A | B4: BR-1 (1 x 18) | C4: cum | D4: =CV1_ROB!D8 -> 841 | E4: =CV1_ROB!G8 -> 0 | F4: =D4-E4 -> 841 | G4: =E4/D4 -> 0
A5: B | B5: ROB-BR-3 (1 x 36 + 1 x 18) | C5: cum | D5: =CV1_ROB!D14 -> 1550 | E5: =CV1_ROB!G14 -> 775 | F5: =D5-E5 -> 775 | G5: =E5/D5 -> 0.5
A6: C | B6: CULVERT-BR-2A | C6: cum | D6: =CV1_ROB!D20 -> 715 | E6: =CV1_ROB!G20 -> 692.25 | F6: =D6-E6 -> 22.75 | G6: =E6/D6 -> 0.96818182
A7: D | B7: CULVERT-BR-2B | C7: cum | D7: =CV1_ROB!D26 -> 885 | E7: =CV1_ROB!G26 -> 624 | F7: =D7-E7 -> 261 | G7: =E7/D7 -> 0.70508475
A8: E | B8: BR-184 | C8: cum | D8: =CV1_ROB!D32 -> 178 | E8: =CV1_ROB!G32 -> 0 | F8: =D8-E8 -> 178 | G8: =E8/D8 -> 0
A9: F | B9: BR-185 | C9: cum | D9: 233 | E9: =CV1_ROB!G38 -> 85 | F9: =CV1_ROB!G38 -> 85 | G9: =E9/D9 -> 0.36480687
A10: G | B10: FOB | C10: cum | D10: =CV1_ROB!D44 -> 52 | E10: =CV1_ROB!G44 -> 0 | F10: =D10-E10 -> 52 | G10: =E10/D10 -> 0
A11: II | B11: Civil2_Infrastructure
A12: A | B12: Station Building | C12: cum | D12: =CV2_Infra!D5 -> 83.714169 | E12: =CV2_Infra!E5 -> 0 | F12: =D12-E12 -> 83.714169 | G12: =E12/D12 -> 0
A13: B | B13: End Goomty (2Nos) | C13: cum | D13: =CV2_Infra!D11 -> 83.145535 | E13: =CV2_Infra!E11 -> 0 | F13: =D13-E13 -> 83.145535 | G13: =E13/D13 -> 0
A14: C | B14: Type - I Quarters (10Nos) | C14: cum | D14: =CV2_Infra!D17 -> 287.19565 | E14: =CV2_Infra!E17 -> 0 | F14: =D14-E14 -> 287.19565 | G14: =E14/D14 -> 0
A15: D | B15: Type - II Quarters(8 Nos) | C15: cum | D15: =CV2_Infra!D23 -> 229.76 | E15: =CV2_Infra!E23 -> 0 | F15: =D15-E15 -> 229.76 | G15: =E15/D15 -> 0
A16: E | B16: Type - III Quarters(4 Nos) | C16: cum | D16: =CV2_Infra!D29 -> 158.04331 | E16: =CV2_Infra!E29 -> 0 | F16: =D16-E16 -> 158.04331 | G16: =E16/D16 -> 0
A17: F | B17: Rest Room | C17: cum | D17: =CV2_Infra!D35 -> 18.94619 | E17: =CV2_Infra!E35 -> 0 | F17: =D17-E17 -> 18.94619 | G17: =E17/D17 -> 0
A18: G | B18: SSE P Way cum Store Room | C18: cum | D18: =CV2_Infra!D41 -> 82.375576 | E18: =CV2_Infra!E41 -> 0 | F18: =D18-E18 -> 82.375576 | G18: =E18/D18 -> 0
A19: III | B19: Civil3_Pway
A20: A | B20: Blanketing(m³) | C20: Cum | D20: =CV3_Pway!D4 -> 49980 | E20: =CV3_Pway!E4 -> 0 | F20: =D20-E20 -> 49980 | G20: =E20/D20 -> 0
A21: B | B21: Ballasting(m³) | C21: Cum | D21: =CV3_Pway!D5 -> 23034 | E21: =CV3_Pway!E5 -> 0 | F21: =D21-E21 -> 23034 | G21: =E21/D21 -> 0
A22: C | B22: Sleeper(nos.) | C22: nos. | D22: =CV3_Pway!D6 -> 17060 | E22: =CV3_Pway!E6 -> 0 | F22: =D22-E22 -> 17060 | G22: =E22/D22 -> 0
A23: D | B23: Track Linking(m) | C23: meter | D23: =CV3_Pway!D7 -> 10270 | E23: =CV3_Pway!E6 -> 0 | F23: =D23-E23 -> 10270 | G23: =E23/D23 -> 0
A24: E | B24: Point & crossing(set) | C24: set | D24: =CV3_Pway!D8 -> 52 | E24: =CV3_Pway!E8 -> 0 | F24: =D24-E24 -> 52 | G24: =E24/D24 -> 0
A25: IV | B25: Earthwork
A26: A | B26: SAIL land(m³) | C26: Cum | D26: =Earthwork!D4 -> 245000 | E26: =Earthwork!E4 -> 190000 | F26: =D26-E26 -> 55000 | G26: =E26/D26 -> 0.7755102
A27: B | B27: Rail Land | C27: Cum | D27: =Earthwork!D5 -> 905000 | E27: =Earthwork!E5 -> 0 | F27: =D27-E27 -> 905000 | G27: =E27/D27 -> 0
A28: C | B28: Total Land(m³) | C28: Cum | D28: =Earthwork!D6 -> 1150000 | E28: =Earthwork!E6 -> 190000 | F28: =D28-E28 -> 960000 | G28: =E28/D28 -> 0.16521739
A29: V

Sheet CV1_ROB
A1: Daily Progress Report | I1: Progress Date :
A2: S No. | B2: description | C2: Uom | D2: Scope | E2: Cum.Executed Qty till last month | F2: Cum.Executed Qty For current month | G2: Cum.Executed Qty till Progress date | H2: Balance Qty | I2: Progress % w.r.t. scope | J2: Remarks
A3: I | B3: BR-1 (1 x 18)
A4: A | B4: Excavation(m³) | C4: Cum | D4: 1213 | E4: 0 | F4: =G4-E4 -> 0 | H4: =D4-G4 -> 1213 | I4: =G4/D4 -> 0 | J4: 1. Area not handed over.
A5: B | B5: PCC(m³) | C5: Cum | D5: 51 | E5: 0 | F5: =G5-E5 -> 0 | H5: =D5-G5 -> 51 | I5: =G5/D5 -> 0
A6: C | B6: Formwork(m²) | C6: Sqm | D6: 1551 | E6: 0 | F6: =G6-E6 -> 0 | H6: =D6-G6 -> 1551 | I6: =G6/D6 -> 0
A7: D | B7: Reinforcement Work(Ton) | C7: Ton | D7: 111 | E7: 0 | F7: =G7-E7 -> 0 | H7: =D7-G7 -> 111 | I7: =G7/D7 -> 0
A8: E | B8: RCC(m³) | C8: Cum | D8: 841 | E8: 0 | F8: =G8-E8 -> 0 | H8: =D8-G8 -> 841 | I8: =G8/D8 -> 0
A9: II | B9: ROB-BR-3 (1 x 36 + 1 x 18)
A10: A | B10: Excavation(m³) | C10: Cum | D10: 3481 | E10: 3032 | F10: =G10-E10 -> 0 | G10: 3032 | H10: =D10-G10 -> 449 | I10: =G10/D10 -> 0.87101408 | J10: 1. Abutment shaft RCC in progress
A11: B | B11: PCC(m³) | C11: Cum | D11: 118 | E11: 52 | F11: =G11-E11 -> 0 | G11: 52 | H11: =D11-G11 -> 66 | I11: =G11/D11 -> 0.44067797
A12: C | B12: Formwork(m²) | C12: Sqm | D12: 2788 | E12: 2566 | F12: =G12-E12 -> 0 | G12: 2566 | H12: =D12-G12 -> 222 | I12: =G12/D12 -> 0.92037303
A13: D | B13: Reinforcement Work(Ton) | C13: Ton | D13: 192 | E13: 133 | F13: =G13-E13 -> 5 | G13: 138 | H13: =D13-G13 -> 54 | I13: =G13/D13 -> 0.71875
A14: E | B14: RCC(m³) | C14: Cum | D14: 1550 | E14: 748 | F14: =G14-E14 -> 27 | G14: 775 | H14: =D14-G14 -> 775 | I14: =G14/D14 -> 0.5
A15: III | B15: CULVERT-BR-2A
A16: A | B16: Excavation(m³) | C16: Cum | D16: 1081 | E16: 1081 | F16: =G16-E16 -> 0 | G16: 1081 | H16: =D16-G16 -> 0 | I16: =G16/D16 -> 1 | J16: 1. raft completed. Wall RCC in progress
A17: B | B17: PCC(m³) | C17: Cum | D17: 203 | E17: 78 | F17: =G17-E17 -> 0 | G17: 78 | H17: =D17-G17 -> 125 | I17: =G17/D17 -> 0.38423645
A18: C | B18: Formwork(m²) | C18: Sqm | D18: 2035 | E18: 1954 | F18: =G18-E18 -> 0 | G18: 1954 | H18: =D18-G18 -> 81 | I18: =G18/D18 -> 0.96019656
A19: D | B19: Reinforcement Work(Ton) | C19: Ton | D19: 72 | E19: 69 | F19: =G19-E19 -> 1 | G19: 70 | H19: =D19-G19 -> 2 | I19: =G19/D19 -> 0.97222222
A20: E | B20: RCC(m³) | C20: Cum | D20: 715 | E20: 665.25 | F20: =G20-E20 -> 27 | G20: 692.25 | H20: =D20-G20 -> 22.75 | I20: =G20/D20 -> 0.96818182
A21: IV | B21: CULVERT-BR-2B
A22: A | B22: Excavation(m³) | C22: Cum | D22: 1357 | E22: 1357 | F22: =G22-E22 -> 0 | G22: 1357 | H22: =D22-G22 -> 0 | I22: =G22/D22 -> 1 | J22: 1. 80% Area handed over on Jan-26. Excavation work in progress.
A23: B | B23: PCC(m³) | C23: Cum | D23: 128 | E23: 43 | F23: =G23-E23 -> 0 | G23: 43 | H23: =D23-G23 -> 85 | I23: =G23/D23 -> 0.3359375
A24: C | B24: Formwork(m²) | C24: Sqm | D24: 1209 | E24: 1162 | F24: =G24-E24 -> 0 | G24: 1162 | H24: =D24-G24 -> 47 | I24: =G24/D24 -> 0.9611249
A25: D | B25: Reinforcement Work(Ton) | C25: Ton | D25: 89 | E25: 77 | F25: =G25-E25 -> 3 | G25: 80 | H25: =D25-G25 -> 9 | I25: =G25/D25 -> 0.8988764
A26: E | B26: RCC(m³) | C26: Cum | D26: 885 | E26: 593 | F26: =G26-E26 -> 31 | G26: 624 | H26: =D26-G26 -> 261 | I26: =G26/D26 -> 0.70508475
A27: V | B27: BR-184
A28: A | B28: Excavation(m³) | C28: Cum | D28: 555 | E28: 0 | F28: =G28-E28 -> 0 | H28: =D28-G28 -> 555 | I28: =G28/D28 -> 0 | J28: 1. Area not handed over.
A29: B | B29: PCC(m³) | C29: Cum | D29: 76 | E29: 0 | F29: =G29-E29 -> 0 | H29: =D29-G29 -> 76 | I29: =G29/D29 -> 0
A30: C | B30: Formwork(m²) | C30: Sqm | D30: 841 | E30: 0 | F30: =G30-E30 -> 0 | H30: =D30-G30 -> 841 | I30: =G30/D30 -> 0
A31: D | B31: Reinforcement Work(Ton) | C31: Ton | D31: 18 | E31: 0 | F31: =G31-E31 -> 0 | H31: =D31-G31 -> 18 | I31: =G31/D31 -> 0
A32: E | B32: RCC(m³) | C32: Cum | D32: 178 | E32: 0 | F32: =G32-E32 -> 0 | H32: =D32-G32 -> 178 | I32: =G32/D32 -> 0
A33: VI | B33: BR-185
A34: A | B34: Excavation(m³) | C34: Cum | D34: 466 | E34: 0 | F34: =G34-E34 -> 0 | H34: =D34-G34 -> 466 | I34: =G34/D34 -> 0 | J34: 1. Area not handed over.
A35: B | B35: PCC(m³) | C35: Cum | D35: 23.3 | E35: 0 | F35: =G35-E35 -> 0 | H35: =D35-G35 -> 23.3 | I35: =G35/D35 -> 0
A36: C | B36: Formwork(m²) | C36: Sqm | D36: 582.5 | E36: 0 | F36: =G36-E36 -> 0 | H36: =D36-G36 -> 582.5 | I36: =G36/D36 -> 0
A37: D | B37: Reinforcement Work(Ton) | C37: Ton | D37: 27.96 | E37: 0 | F37: =G37-E37 -> 0 | H37: =D37-G37 -> 27.96 | I37: =G37/D37 -> 0
A38: E | B38: RCC(m³) | C38: Cum | D38: 233 | E38: 0 | F38: =G38-E38 -> 85 | G38: 85 | H38: =D38-G38 -> 148 | I38: =G38/D38 -> 0.36480687
A39: VII | B39: FOB
A40: A | B40: Excavation(m³) | C40: Cum | D40: 55 | E40: 0 | F40: =G40-E40 -> 0 | H40: =D40-G40 -> 55 | I40: =G40/D40 -> 0 | J40: 1. Area not handed over.
...

Sheet CV2_Infra
A1: Daily Progress Report | G1: Progress Date : | H1: 46188
A2: S No. | B2: Description of Item | C2: Uom | D2: Scope | E2: Cum.Executed Qty till Progress date | F2: Balance Qty | G2: Progress % w.r.t. scope | H2: Remarks
A3: I | B3: Station Building
A4: A | B4: Excavation(m³) | C4: Cum | D4: 65.794532 | F4: =D4-E4 -> 65.794532 | G4: =E4/D4 -> 0
A5: B | B5: RCC(m³) | C5: Cum | D5: 83.714169 | F5: =D5-E5 -> 83.714169 | G5: =E5/D5 -> 0
A6: C | B6: Formwork(m²) | C6: sqm | D6: 403.61665 | F6: =D6-E6 -> 403.61665 | G6: =E6/D6 -> 0
A7: D | B7: Brick work(m³) | C7: cum | D7: 186 | F7: =D7-E7 -> 186 | G7: =E7/D7 -> 0
A8: E | B8: Finishing(m²) | C8: Sqm | D8: 2846 | F8: =D8-E8 -> 2846 | G8: =E8/D8 -> 0
A9: II | B9: End Goomty (2Nos)
A10: A | B10: Excavation(m³) | C10: Cum | D10: 106.69151 | F10: =D10-E10 -> 106.69151 | G10: =E10/D10 -> 0
A11: B | B11: RCC(m³) | C11: Cum | D11: 83.145535 | F11: =D11-E11 -> 83.145535 | G11: =E11/D11 -> 0
A12: C | B12: Formwork(m²) | C12: sqm | D12: 655.11446 | F12: =D12-E12 -> 655.11446 | G12: =E12/D12 -> 0
A13: D | B13: Brick work(m³) | C13: cum | D13: 187 | F13: =D13-E13 -> 187 | G13: =E13/D13 -> 0
A14: E | B14: Finishing(m²) | C14: Sqm | D14: 3038 | F14: =D14-E14 -> 3038 | G14: =E14/D14 -> 0
A15: III | B15: Type - I Quarters (10Nos)
A16: A | B16: Excavation(m³) | C16: Cum | D16: 286.89478 | F16: =D16-E16 -> 286.89478 | G16: =E16/D16 -> 0
A17: B | B17: RCC(m³) | C17: Cum | D17: 287.19565 | F17: =D17-E17 -> 287.19565 | G17: =E17/D17 -> 0
A18: C | B18: Formwork(m²) | C18: sqm | D18: 2893.37 | F18: =D18-E18 -> 2893.37 | G18: =E18/D18 -> 0
A19: D | B19: Brick work(m³) | C19: cum | D19: 301 | F19: =D19-E19 -> 301 | G19: =E19/D19 -> 0
A20: E | B20: Finishing(m²) | C20: Sqm | D20: 7815 | F20: =D20-E20 -> 7815 | G20: =E20/D20 -> 0
A21: IV | B21: Type - II Quarters (8 Nos)
A22: A | B22: Excavation(m³) | C22: Cum | D22: 229.51583 | F22: =D22-E22 -> 229.51583 | G22: =E22/D22 -> 0
A23: B | B23: RCC(m³) | C23: Cum | D23: 229.76 | F23: =D23-E23 -> 229.76 | G23: =E23/D23 -> 0
A24: C | B24: Formwork(m²) | C24: sqm | D24: 2314 | F24: =D24-E24 -> 2314 | G24: =E24/D24 -> 0
A25: D | B25: Brick work(m³) | C25: cum | D25: 241 | F25: =D25-E25 -> 241 | G25: =E25/D25 -> 0
A26: E | B26: Finishing(m²) | C26: Sqm | D26: 6252 | F26: =D26-E26 -> 6252 | G26: =E26/D26 -> 0
A27: V | B27: Type - III Quarters (4 Nos)
A28: A | B28: Excavation(m³) | C28: Cum | D28: 231.11708 | F28: =D28-E28 -> 231.11708 | G28: =E28/D28 -> 0
A29: B | B29: RCC(m³) | C29: Cum | D29: 158.04331 | F29: =D29-E29 -> 158.04331 | G29: =E29/D29 -> 0
A30: C | B30: Formwork(m²) | C30: sqm | D30: 1645 | F30: =D30-E30 -> 1645 | G30: =E30/D30 -> 0
A31: D | B31: Brick work(m³) | C31: cum | D31: 119 | F31: =D31-E31 -> 119 | G31: =E31/D31 -> 0
A32: E | B32: Finishing(m²) | C32: Sqm | D32: 4226 | F32: =D32-E32 -> 4226 | G32: =E32/D32 -> 0
A33: VI | B33: Rest Room
A34: A | B34: Excavation(m³) | C34: Cum | D34: 24.793115 | F34: =D34-E34 -> 24.793115 | G34: =E34/D34 -> 0
A35: B | B35: RCC(m³) | C35: Cum | D35: 18.94619 | F35: =D35-E35 -> 18.94619 | G35: =E35/D35 -> 0
A36: C | B36: Formwork(m²) | C36: sqm | D36: 148 | F36: =D36-E36 -> 148 | G36: =E36/D36 -> 0
A37: D | B37: Brick work(m³) | C37: cum | D37: 43 | F37: =D37-E37 -> 43 | G37: =E37/D37 -> 0
A38: E | B38: Finishing(m²) | C38: Sqm | D38: 688 | F38: =D38-E38 -> 688 | G38: =E38/D38 -> 0
A39: VII | B39: SSE P Way cum Store Room
A40: A | B40: Excavation(m³) | C40: Cum | D40: 57.1428 | F40: =D40-E40 -> 57.1428 | G40: =E40/D40 -> 0
...

Sheet CV3_Pway
A1: Daily Progress Report | G1: Progress Date : | H1: 46188
A2: S No. | B2: Description of Item | C2: Uom | D2: Scope | E2: Executed Qty till Progress date | F2: Balance Qty | G2: Progress % w.r.t. scope | H2: Remarks
A3: I | B3: PWAY tracks
A4: A | B4: Blanketing(m³) | C4: Cum | D4: 49980 | F4: =D4-E4 -> 49980 | G4: =E4/D4 -> 0
A5: B | B5: Ballasting(m³) | C5: Cum | D5: 23034 | F5: =D5-E5 -> 23034 | G5: =E5/D5 -> 0
A6: C | B6: Sleeper(nos.) | C6: nos. | D6: 17060 | F6: =D6-E6 -> 17060 | G6: =E6/D6 -> 0
A7: D | B7: Track Linking(m) | C7: meter | D7: =10270 -> 10270 | F7: =D7-E7 -> 10270 | G7: =E6/D7 -> 0
A8: E | B8: Point & crossing(set) | C8: set | D8: 52 | F8: =D8-E8 -> 52 | G8: =E8/D8 -> 0

Sheet Earthwork
A1: Daily Progress Report | G1: Progress Date : | H1: 46188
A2: S No. | B2: Description of Item | C2: Uom | D2: Scope | E2: Executed Qty till Progress date | F2: Balance Qty | G2: Progress % w.r.t. scope | H2: Remarks
A3: I | B3: Earthwork
A4: A | B4: SAIL land(m³) | C4: Cum | D4: 245000 | E4: 190000 | F4: =D4-E4 -> 55000 | G4: =E4/D4 -> 0.7755102
A5: B | B5: RAIL Land(m³) | C5: Cum | D5: 905000 | E5: 0 | F5: =D5-E5 -> 905000 | G5: =E5/D5 -> 0
A6: C | B6: Total Land(m³) | C6: Cum | D6: 1150000 | E6: 190000 | F6: =D6-E6 -> 960000 | G6: =E6/D6 -> 0.16521739
